Workbook

Sheet README
A1: ShadowFox Data Analyst Internship - Intermediate Level
A2: Intern: Rudra Kumar | SF-PID: SF-PID-2026-W6251 | Amrita Vishwa Vidyapeetham, Nagercoil
A4: Project: Customer and Revenue Analysis (Jan-Dec 2025)
A5: DATA NOTE: This is a SAMPLE dataset created for this exercise. It is not real company data.
A6: Currency is Indian Rupees (INR).
A8: Sheets
A9: Dashboard - KPIs and charts
A10: Insights - findings, reasons and recommendations
A11: Raw_Data - data before cleaning
A12: Cleaning_Log - each cleaning step and rows affected
A13: Clean_Data - cleaned order lines. Revenue and Profit are formulas.
A14: Customers - one row per customer, sorted by revenue (high to low), built with formulas
... A22: Top 10% share = revenue of the top 10% of customers / total revenue

Sheet Dashboard
A1: Customer and Revenue Dashboard - 2025 (Sample Data)
A3: Total Revenue (INR) | D3: Total Profit (INR) | G3: Profit Margin | J3: Total Orders
A4: =Analysis!C16 -> 20571768 | D4: =Analysis!D16 -> 6248167.5 | G4: =Analysis!D16/Analysis!C16 -> 0.30372536 | J4: =Analysis!E16 -> 2085
A6: Customers | D6: Repeat Rate | G6: Top 10% Customers Share | J6: Avg Order Value (INR)
A7: =Analysis!P4 -> 799 | D7: =Analysis!P6 -> 0.58197747 | G7: =Analysis!P10 -> 0.42432013 | J7: =Analysis!P14 -> 9866.5552

Sheet Insights
A1: Key Insights, Possible Reasons and Recommendations (sample dataset)
A3: What the data shows
A4: 1. Revenue is INR 205.72 lakh from 2085 orders and 799 customers. Profit is INR 62.48 lakh, a margin of 30.4%.
A5: 2. 58.2% of customers ordered more than once (465 customers). They bring 88.3% of revenue.
A6: 3. 41.8% of customers ordered only once. They are the largest single group but bring only 11.7% of revenue.
A7: 4. Revenue is concentrated. The top 10% of customers give 42.4% of revenue. The top 20% give 62.3%. The bottom 50% give only 10.2%.
A8: 5. Corporate customers spend most per customer (INR 0.87 lakh), against INR 0.14 lakh for Consumer and INR 0.25 lakh for Small Business.
A9: 6. Seasonality: Dec is the best month (INR 20.97 lakh) and Jul is the weakest (INR 12.37 lakh). Oct to Dec give 28.7% of yearly revenue.
A10: 7. Margins differ by category: Electronics 27.8%, Furniture 28.5%, Stationery 48.7%. South is the top region with 33.3% of revenue.
A12: Possible reasons
A13: - Corporate buyers order larger quantities, so a small group lifts revenue per customer.
A14: - November and December are strong months. Extra Q4 discounts may help volume.
... A26: All figures come from the Analysis sheet. The data is a sample, so use the results for practice only.

Sheet Raw_Data
A1: OrderID | B1: CustomerID | C1: Date | D1: Region | E1: Segment | F1: Category | G1: Product | H1: Qty | I1: UnitPrice | J1: Discount | K1: UnitCost
A2: ORD5001 | B2: C0001 | C2: 45719 | D2: North | E2: Consumer | F2: Stationery | G2: Planner | H2: 3 | I2: 600 | J2: 0 | K2: 300
A3: ORD5002 | B3: C0002 | C3: 45998 | D3: North | E3: Small Business | F3: Electronics | G3: Headphones | H3: 5 | I3: 2500 | J3: 0.15 | K3: 1600
A4: ORD5003 | B4: C0002 | C4: 45696 | D4: North | E4: Small Business | F4: Furniture | G4: Office Chair | H4: 4 | I4: 7000 | J4: 0 | K4: 4800
A5: ORD5004 | B5: C0003 | C5: 45995 | D5: South | E5: Consumer | F5: Stationery | G5: Notebook Set | H5: 6 | I5: 400 | J5: 0.15 | K5: 200
A6: ORD5005 | B6: C0004 | C6: 45943 | D6: East | E6: Small Business | F6: Stationery | G6: Pen Pack | H6: 6 | I6: 250 | J6: 0.15 | K6: 100
A7: ORD5006 | B7: C0004 | C7: 45910 | D7: East | E7: Small Business | F7: Furniture | G7: Office Chair | H7: 1 | I7: 7000 | J7: 0 | K7: 4800
A8: ORD5007 | B8: C0004 | C8: 46001 | D8: East | E8: Small Business | F8: Furniture | G8: Desk Lamp | H8: 5 | I8: 1200 | J8: 0.15 | K8: 600
A9: ORD5008 | B9: C0004 | C9: 45881 | D9: East | E9: Small Business | F9: Furniture | G9: Study Desk | H9: 5 | I9: 9000 | J9: 0 | K9: 6200
A10: ORD5009 | B10: C0004 | C10: 45920 | D10: East | E10: Small Business | F10: Stationery | G10: Notebook Set | H10: 7 | I10: 400 | J10: 0 | K10: 200
A11: ORD5010 | B11: C0005 | C11: 45823 | D11: West | E11: Corporate | F11: Furniture | G11: Study Desk | H11: 5 | I11: 9000 | J11: 0.1 | K11: 6200
A12: ORD5011 | B12: C0005 | C12: 45953 | E12: Corporate | F12: Furniture | G12: Desk Lamp | H12: 3 | I12: 1200 | J12: 0.1 | K12: 600
A13: ORD5012 | B13: C0005 | C13: 45727 | D13: West | E13: Corporate | F13: Furniture | G13: Study Desk | H13: 4 | I13: 9000 | J13: 0.15 | K13: 6200
A14: ORD5013 | B14: C0006 | C14: 45917 | D14: North | E14: Consumer | F14: Electronics | G14: Bluetooth Speaker | H14: 2 | I14: 3000 | J14: 0 | K14: 2000
A15: ORD5014 | B15: C0007 | C15: 45671 | D15: West | E15: Consumer | F15: Furniture | G15: Desk Lamp | H15: 1 | I15: 1200 | J15: 0.05 | K15: 600
A16: ORD5015 | B16: C0008 | C16: 46010 | D16: East | E16: Consumer | F16: Furniture | G16: Office Chair | H16: 3 | I16: 7000 | J16: 0.15 | K16: 4800
A17: ORD5016 | B17: C0009 | C17: 46010 | D17: East | E17: Consumer | F17: Furniture | G17: Bookshelf | H17: 2 | I17: 5500 | J17: 0.1 | K17: 3600
A18: ORD5017 | B18: C0010 | C18: 45977 | D18: North | E18: Consumer | F18: Stationery | G18: Marker Set | H18: 2 | I18: 500 | J18: 0.05 | K18: 250
A19: ORD5018 | B19: C0010 | C19: 45922 | D19: North | E19: Consumer | F19: Stationery | G19: Notebook Set | H19: 2 | I19: 400 | J19: 0.1 | K19: 200
A20: ORD5019 | B20: C0010 | C20: 45931 | D20: North | E20: Consumer | F20: Furniture | G20: Desk Lamp | H20: 2 | I20: 1200 | J20: 0.05 | K20: 600
A21: ORD5020 | B21: C0010 | C21: 46007 | D21: North | E21: Consumer | F21: Stationery | G21: Marker Set | H21: 4 | I21: 500 | J21: 0.05 | K21: 250
A22: ORD5021 | B22: C0010 | C22: 45974 | D22: North | E22: Consumer | F22: Electronics | G22: Headphones | H22: 1 | I22: 2500 | J22: 0.05 | K22: 1600
A23: ORD5022 | B23: C0011 | C23: 45884 | D23: North | E23: Small Business | F23: Stationery | G23: Marker Set | H23: 20 | I23: 500 | J23: 0 | K23: 250
A24: ORD5023 | B24: C0011 | C24: 45958 | D24: North | E24: Small Business | F24: Electronics | G24: Bluetooth Speaker | H24: 3 | I24: 3000 | J24: 0.1 | K24: 2000
... A178: ORD5177 | B178: C0064 | C178: 45871 | D178: South | E178: Consumer | F178: Furniture | G178: Desk Lamp | H178: 1 | I178: 1200 | J178: 0.05 | K178: 600
A179: ORD5178 | C179: 45878 | D179: South | E179: Consumer | F179: Electronics | G179: Bluetooth Speaker | H179: 1 | I179: 3000 | J179: 0 | K179: 2000
A180: ORD5179 | B180: C0065 | C180: 46003 | D180: South | E180: Consumer | F180: Furniture | G180: Study Desk | H180: 3 | I180: 9000 | J180: 0.05 | K180: 6200
A181: ORD5180 | B181: C0066 | C181: 46015 | D181: North | E181: Consumer | F181: Electronics | G181: Power Bank | H181: 2 | I181: 1500 | J181: 0.05 | K181: 900
A182: ORD5181 | B182: C0066 | C182: 45683 | D182: North | E182: Consumer | F182: Stationery | G182: Planner | H182: 4 | I182: 600 | J182: 0.1 | K182: 300
A183: ORD5182 | B183: C0066 | C183: 45984 | D183: North | E183: Consumer | F183: Electronics | G183: Headphones | H183: 1 | I183: 2500 | J183: 0.1 | K183: 1600
A184: ORD5183 | B184: C0066 | C184: 45752 | D184: North | E184: Consumer | F184: Electronics | G184: Bluetooth Speaker | H184: 2 | I184: 3000 | J184: 0.05 | K184: 2000
A185: ORD5184 | B185: C0066 | C185: 45957 | D185: North | E185: Consumer | F185: Electronics | G185: Bluetooth Speaker | H185: 1 | I185: 3000 | J185: 0.05 | K185: 2000
A186: ORD5185 | B186: C0066 | C186: 45976 | D186: North | E186: Consumer | F186: Stationery | G186: Pen Pack | H186: 6 | I186: 250 | J186: 0.05 | K186: 100
A187: ORD5186 | B187: C0067 | C187: 45851 | D187: East | E187: Corporate | F187: Furniture | G187: Bookshelf | H187: 6 | I187: 5500 | J187: 0.05 | K187: 3600
A188: ORD5187 | B188: C0067 | C188: 45854 | D188: South | E188: Corporate | F188: Furniture | G188: Study Desk | H188: 2 | I188: 9000 | J188: 0 | K188: 6200
A189: ORD5188 | B189: C0067 | C189: 45939 | D189: East | E189: Corporate | F189: Furniture | G189: Bookshelf | H189: 2 | I189: 5500 | J189: 0.05 | K189: 3600
A190: ORD5189 | B190: C0067 | C190: 45711 | D190: East | E190: Corporate | F190: Electronics | G190: Headphones | H190: 5 | I190: 2500 | J190: 0.15 | K190: 1600
A191: ORD5190 | B191: C0068 | C191: 45762 | D191: West | E191: Corporate | F191: Furniture | G191: Desk Lamp | H191: 3 | I191: 1200 | J191: 0.15 | K191: 600
... A215: ORD5214 | B215: C0072 | C215: 45950 | D215: South | E215: Consumer | F215: Stationery | G215: Pen Pack | H215: 7 | I215: 250 | J215: 0.15 | K215: 100
A216: ORD5215 | B216: C0072 | C216: 45940 | E216: Consumer | F216: Stationery | G216: Planner | H216: 7 | I216: 600 | J216: 0.05 | K216: 300
...

Sheet Cleaning_Log
A1: Step | B1: Action | C1: Rows affected
A2: Start | B2: Rows in raw data | C2: 2132
A3: 1 | B3: Removed exact duplicate rows | C3: 20
A4: 2 | B4: Trimmed spaces and fixed text case in Region | C4: 26
A5: 3 | B5: Missing Region labelled "Unspecified" (rows kept) | C5: 10
A6: 4 | B6: Removed rows with missing CustomerID (cannot be used for customer analysis) | C6: 15
A7: 5 | B7: Removed rows with missing Qty (revenue cannot be calculated) | C7: 12
A8: End | B8: Rows in clean data | C8: 2085

Sheet Clean_Data
A1: OrderID | B1: CustomerID | C1: Date | D1: Month | E1: Region | F1: Segment | G1: Category | H1: Product | I1: Qty | J1: UnitPrice | K1: Discount | L1: UnitCost | M1: Revenue | N1: Profit
A2: ORD5260 | B2: C0094 | C2: 45658 | D2: =MONTH(C2) -> 1 | E2: South | F2: Small Business | G2: Electronics | H2: Headphones | I2: 4 | J2: 2500 | K2: 0.1 | L2: 1600 | M2: =I2*J2*(1-K2) -> 9000 | N2: =M2-I2*L2 -> 2600
A3: ORD5836 | B3: C0320 | C3: 45658 | D3: =MONTH(C3) -> 1 | E3: South | F3: Small Business | G3: Stationery | H3: Pen Pack | I3: 5 | J3: 250 | K3: 0 | L3: 100 | M3: =I3*J3*(1-K3) -> 1250 | N3: =M3-I3*L3 -> 750
A4: ORD5843 | B4: C0323 | C4: 45658 | D4: =MONTH(C4) -> 1 | E4: East | F4: Consumer | G4: Furniture | H4: Study Desk | I4: 2 | J4: 9000 | K4: 0.1 | L4: 6200 | M4: =I4*J4*(1-K4) -> 16200 | N4: =M4-I4*L4 -> 3800
A5: ORD6044 | B5: C0401 | C5: 45658 | D5: =MONTH(C5) -> 1 | E5: East | F5: Small Business | G5: Electronics | H5: Power Bank | I5: 1 | J5: 1500 | K5: 0.1 | L5: 900 | M5: =I5*J5*(1-K5) -> 1350 | N5: =M5-I5*L5 -> 450
A6: ORD6339 | B6: C0496 | C6: 45658 | D6: =MONTH(C6) -> 1 | E6: South | F6: Corporate | G6: Furniture | H6: Desk Lamp | I6: 5 | J6: 1200 | K6: 0 | L6: 600 | M6: =I6*J6*(1-K6) -> 6000 | N6: =M6-I6*L6 -> 3000
A7: ORD5592 | B7: C0233 | C7: 45659 | D7: =MONTH(C7) -> 1 | E7: West | F7: Small Business | G7: Furniture | H7: Desk Lamp | I7: 2 | J7: 1200 | K7: 0.1 | L7: 600 | M7: =I7*J7*(1-K7) -> 2160 | N7: =M7-I7*L7 -> 960
A8: ORD5733 | B8: C0279 | C8: 45659 | D8: =MONTH(C8) -> 1 | E8: East | F8: Consumer | G8: Furniture | H8: Office Chair | I8: 2 | J8: 7000 | K8: 0 | L8: 4800 | M8: =I8*J8*(1-K8) -> 14000 | N8: =M8-I8*L8 -> 4400
A9: ORD6342 | B9: C0497 | C9: 45659 | D9: =MONTH(C9) -> 1 | E9: West | F9: Consumer | G9: Electronics | H9: Power Bank | I9: 2 | J9: 1500 | K9: 0.05 | L9: 900 | M9: =I9*J9*(1-K9) -> 2850 | N9: =M9-I9*L9 -> 1050
A10: ORD6463 | B10: C0540 | C10: 45659 | D10: =MONTH(C10) -> 1 | E10: South | F10: Small Business | G10: Stationery | H10: Planner | I10: 15 | J10: 600 | K10: 0 | L10: 300 | M10: =I10*J10*(1-K10) -> 9000 | N10: =M10-I10*L10 -> 4500
A11: ORD6593 | B11: C0598 | C11: 45659 | D11: =MONTH(C11) -> 1 | E11: South | F11: Consumer | G11: Stationery | H11: Marker Set | I11: 2 | J11: 500 | K11: 0.1 | L11: 250 | M11: =I11*J11*(1-K11) -> 900 | N11: =M11-I11*L11 -> 400
A12: ORD6900 | B12: C0717 | C12: 45659 | D12: =MONTH(C12) -> 1 | E12: South | F12: Small Business | G12: Stationery | H12: Notebook Set | I12: 5 | J12: 400 | K12: 0 | L12: 200 | M12: =I12*J12*(1-K12) -> 2000 | N12: =M12-I12*L12 -> 1000
A13: ORD7093 | B13: C0794 | C13: 45659 | D13: =MONTH(C13) -> 1 | E13: North | F13: Consumer | G13: Electronics | H13: Smart Watch | I13: 2 | J13: 4500 | K13: 0 | L13: 3300 | M13: =I13*J13*(1-K13) -> 9000 | N13: =M13-I13*L13 -> 2400
... A2086: ORD6276 | B2086: C0480 | C2086: 46019 | D2086: =MONTH(C2086) -> 12 | E2086: North | F2086: Consumer | G2086: Electronics | H2086: Smart Watch | I2086: 1 | J2086: 4500 | K2086: 0.05 | L2086: 3300 | M2086: =I2086*J2086*(1-K2086) -> 4275 | N2086: =M2086-I2086*L2086 -> 975

Sheet Customers
A1: CustomerID | B1: Segment | C1: Orders | D1: Revenue | E1: Profit | F1: Type | G1: Cumulative Share
A2: C0347 | B2: =INDEX(Clean_Data!$F$2:$F$2086,MATCH(A2,Clean_Data!$B$2:$B$2086,0)) -> Corporate | C2: =COUNTIFS(Clean_Data!$B$2:$B$2086,A2) -> 9 | D2: =SUMIFS(Clean_Data!$M$2:$M$2086,Clean_Data!$B$2:$B$2086,A2) -> 280930 | E2: =SUMIFS(Clean_Data!$N$2:$N$2086,Clean_Data!$B$2:$B$2086,A2) -> 75930 | F2: =IF(C2>1,"Repeat","One-time") -> Repeat | G2: =SUM($D$2:D2)/SUM($D$2:$D$800) -> 0.013656094
A3: C0133 | B3: =INDEX(Clean_Data!$F$2:$F$2086,MATCH(A3,Clean_Data!$B$2:$B$2086,0)) -> Corporate | C3: =COUNTIFS(Clean_Data!$B$2:$B$2086,A3) -> 11 | D3: =SUMIFS(Clean_Data!$M$2:$M$2086,Clean_Data!$B$2:$B$2086,A3) -> 276420 | E3: =SUMIFS(Clean_Data!$N$2:$N$2086,Clean_Data!$B$2:$B$2086,A3) -> 78920 | F3: =IF(C3>1,"Repeat","One-time") -> Repeat | G3: =SUM($D$2:D3)/SUM($D$2:$D$800) -> 0.027092956
A4: C0432 | B4: =INDEX(Clean_Data!$F$2:$F$2086,MATCH(A4,Clean_Data!$B$2:$B$2086,0)) -> Corporate | C4: =COUNTIFS(Clean_Data!$B$2:$B$2086,A4) -> 13 | D4: =SUMIFS(Clean_Data!$M$2:$M$2086,Clean_Data!$B$2:$B$2086,A4) -> 244640 | E4: =SUMIFS(Clean_Data!$N$2:$N$2086,Clean_Data!$B$2:$B$2086,A4) -> 68240 | F4: =IF(C4>1,"Repeat","One-time") -> Repeat | G4: =SUM($D$2:D4)/SUM($D$2:$D$800) -> 0.038984983
A5: C0504 | B5: =INDEX(Clean_Data!$F$2:$F$2086,MATCH(A5,Clean_Data!$B$2:$B$2086,0)) -> Corporate | C5: =COUNTIFS(Clean_Data!$B$2:$B$2086,A5) -> 6 | D5: =SUMIFS(Clean_Data!$M$2:$M$2086,Clean_Data!$B$2:$B$2086,A5) -> 230300 | E5: =SUMIFS(Clean_Data!$N$2:$N$2086,Clean_Data!$B$2:$B$2086,A5) -> 61500 | F5: =IF(C5>1,"Repeat","One-time") -> Repeat | G5: =SUM($D$2:D5)/SUM($D$2:$D$800) -> 0.050179937
A6: C0025 | B6: =INDEX(Clean_Data!$F$2:$F$2086,MATCH(A6,Clean_Data!$B$2:$B$2086,0)) -> Corporate | C6: =COUNTIFS(Clean_Data!$B$2:$B$2086,A6) -> 8 | D6: =SUMIFS(Clean_Data!$M$2:$M$2086,Clean_Data!$B$2:$B$2086,A6) -> 224650 | E6: =SUMIFS(Clean_Data!$N$2:$N$2086,Clean_Data!$B$2:$B$2086,A6) -> 59650 | F6: =IF(C6>1,"Repeat","One-time") -> Repeat | G6: =SUM($D$2:D6)/SUM($D$2:$D$800) -> 0.061100243
A7: C0400 | B7: =INDEX(Clean_Data!$F$2:$F$2086,MATCH(A7,Clean_Data!$B$2:$B$2086,0)) -> Corporate | C7: =COUNTIFS(Clean_Data!$B$2:$B$2086,A7) -> 5 | D7: =SUMIFS(Clean_Data!$M$2:$M$2086,Clean_Data!$B$2:$B$2086,A7) -> 209825 | E7: =SUMIFS(Clean_Data!$N$2:$N$2086,Clean_Data!$B$2:$B$2086,A7) -> 59925 | F7: =IF(C7>1,"Repeat","One-time") -> Repeat | G7: =SUM($D$2:D7)/SUM($D$2:$D$800) -> 0.071299902
A8: C0225 | B8: =INDEX(Clean_Data!$F$2:$F$2086,MATCH(A8,Clean_Data!$B$2:$B$2086,0)) -> Corporate | C8: =COUNTIFS(Clean_Data!$B$2:$B$2086,A8) -> 5 | D8: =SUMIFS(Clean_Data!$M$2:$M$2086,Clean_Data!$B$2:$B$2086,A8) -> 184650 | E8: =SUMIFS(Clean_Data!$N$2:$N$2086,Clean_Data!$B$2:$B$2086,A8) -> 41850 | F8: =IF(C8>1,"Repeat","One-time") -> Repeat | G8: =SUM($D$2:D8)/SUM($D$2:$D$800) -> 0.080275795
A9: C0216 | B9: =INDEX(Clean_Data!$F$2:$F$2086,MATCH(A9,Clean_Data!$B$2:$B$2086,0)) -> Corporate | C9: =COUNTIFS(Clean_Data!$B$2:$B$2086,A9) -> 8 | D9: =SUMIFS(Clean_Data!$M$2:$M$2086,Clean_Data!$B$2:$B$2086,A9) -> 179875 | E9: =SUMIFS(Clean_Data!$N$2:$N$2086,Clean_Data!$B$2:$B$2086,A9) -> 46175 | F9: =IF(C9>1,"Repeat","One-time") -> Repeat | G9: =SUM($D$2:D9)/SUM($D$2:$D$800) -> 0.089019575
A10: C0798 | B10: =INDEX(Clean_Data!$F$2:$F$2086,MATCH(A10,Clean_Data!$B$2:$B$2086,0)) -> Corporate | C10: =COUNTIFS(Clean_Data!$B$2:$B$2086,A10) -> 5 | D10: =SUMIFS(Clean_Data!$M$2:$M$2086,Clean_Data!$B$2:$B$2086,A10) -> 178700 | E10: =SUMIFS(Clean_Data!$N$2:$N$2086,Clean_Data!$B$2:$B$2086,A10) -> 47500 | F10: =IF(C10>1,"Repeat","One-time") -> Repeat | G10: =SUM($D$2:D10)/SUM($D$2:$D$800) -> 0.097706237
A11: C0422 | B11: =INDEX(Clean_Data!$F$2:$F$2086,MATCH(A11,Clean_Data!$B$2:$B$2086,0)) -> Corporate | C11: =COUNTIFS(Clean_Data!$B$2:$B$2086,A11) -> 11 | D11: =SUMIFS(Clean_Data!$M$2:$M$2086,Clean_Data!$B$2:$B$2086,A11) -> 174880 | E11: =SUMIFS(Clean_Data!$N$2:$N$2086,Clean_Data!$B$2:$B$2086,A11) -> 44880 | F11: =IF(C11>1,"Repeat","One-time") -> Repeat | G11: =SUM($D$2:D11)/SUM($D$2:$D$800) -> 0.10620721
A12: C0622 | B12: =INDEX(Clean_Data!$F$2:$F$2086,MATCH(A12,Clean_Data!$B$2:$B$2086,0)) -> Corporate | C12: =COUNTIFS(Clean_Data!$B$2:$B$2086,A12) -> 7 | D12: =SUMIFS(Clean_Data!$M$2:$M$2086,Clean_Data!$B$2:$B$2086,A12) -> 160415 | E12: =SUMIFS(Clean_Data!$N$2:$N$2086,Clean_Data!$B$2:$B$2086,A12) -> 44415 | F12: =IF(C12>1,"Repeat","One-time") -> Repeat | G12: =SUM($D$2:D12)/SUM($D$2:$D$800) -> 0.11400503
A13: C0482 | B13: =INDEX(Clean_Data!$F$2:$F$2086,MATCH(A13,Clean_Data!$B$2:$B$2086,0)) -> Corporate | C13: =COUNTIFS(Clean_Data!$B$2:$B$2086,A13) -> 8 | D13: =SUMIFS(Clean_Data!$M$2:$M$2086,Clean_Data!$B$2:$B$2086,A13) -> 159150 | E13: =SUMIFS(Clean_Data!$N$2:$N$2086,Clean_Data!$B$2:$B$2086,A13) -> 47350 | F13: =IF(C13>1,"Repeat","One-time") -> Repeat | G13: =SUM($D$2:D13)/SUM($D$2:$D$800) -> 0.12174136
... A800: C0245 | B800: =INDEX(Clean_Data!$F$2:$F$2086,MATCH(A800,Clean_Data!$B$2:$B$2086,0)) -> Consumer | C800: =COUNTIFS(Clean_Data!$B$2:$B$2086,A800) -> 1 | D800: =SUMIFS(Clean_Data!$M$2:$M$2086,Clean_Data!$B$2:$B$2086,A800) -> 425 | E800: =SUMIFS(Clean_Data!$N$2:$N$2086,Clean_Data!$B$2:$B$2086,A800) -> 225 | F800: =IF(C800>1,"Repeat","One-time") -> One-time | G800: =SUM($D$2:D800)/SUM($D$2:$D$800) -> 1

Sheet Analysis
A1: Summary tables (all values calculated from Clean_Data and Customers)
A3: Month No | B3: Month | C3: Revenue | D3: Profit | E3: Orders | F3: MoM Growth | G3: Seasonality Index | I3: Orders per customer | J3: Customers | K3: Share of Customers | L3: Revenue | M3: Share of Revenue | O3: Customer KPI | P3: Value
A4: 1 | B4: Jan | C4: =SUMIFS(Clean_Data!$M$2:$M$2086,Clean_Data!$D$2:$D$2086,A4) -> 1484130 | D4: =SUMIFS(Clean_Data!$N$2:$N$2086,Clean_Data!$D$2:$D$2086,A4) -> 472880 | E4: =COUNTIFS(Clean_Data!$D$2:$D$2086,A4) -> 147 | G4: =C4/AVERAGE($C$4:$C$15) -> 0.86572824 | I4: 1 order | J4: =COUNTIFS(Customers!$C$2:$C$800,1) -> 334 | K4: =J4/$J$9 -> 0.41802253 | L4: =SUMIFS(Customers!$D$2:$D$800,Customers!$C$2:$C$800,1) -> 2413890 | M4: =L4/$L$9 -> 0.11733994 | O4: Total customers | P4: =COUNTA(Customers!$A$2:$A$800) -> 799
A5: 2 | B5: Feb | C5: =SUMIFS(Clean_Data!$M$2:$M$2086,Clean_Data!$D$2:$D$2086,A5) -> 1500235 | D5: =SUMIFS(Clean_Data!$N$2:$N$2086,Clean_Data!$D$2:$D$2086,A5) -> 466735 | E5: =COUNTIFS(Clean_Data!$D$2:$D$2086,A5) -> 157 | F5: =IF(C4=0,0,C5/C4-1) -> 0.010851475 | G5: =C5/AVERAGE($C$4:$C$15) -> 0.87512267 | I5: 2 orders | J5: =COUNTIFS(Customers!$C$2:$C$800,2) -> 169 | K5: =J5/$J$9 -> 0.21151439 | L5: =SUMIFS(Customers!$D$2:$D$800,Customers!$C$2:$C$800,2) -> 2913377.5 | M5: =L5/$L$9 -> 0.14162018 | O5: Repeat customers | P5: =COUNTIF(Customers!$F$2:$F$800,"Repeat") -> 465
A6: 3 | B6: Mar | C6: =SUMIFS(Clean_Data!$M$2:$M$2086,Clean_Data!$D$2:$D$2086,A6) -> 1587085 | D6: =SUMIFS(Clean_Data!$N$2:$N$2086,Clean_Data!$D$2:$D$2086,A6) -> 505435 | E6: =COUNTIFS(Clean_Data!$D$2:$D$2086,A6) -> 153 | F6: =IF(C5=0,0,C6/C5-1) -> 0.05789093 | G6: =C6/AVERAGE($C$4:$C$15) -> 0.92578433 | I6: 3 orders | J6: =COUNTIFS(Customers!$C$2:$C$800,3) -> 109 | K6: =J6/$J$9 -> 0.13642053 | L6: =SUMIFS(Customers!$D$2:$D$800,Customers!$C$2:$C$800,3) -> 3469285 | M6: =L6/$L$9 -> 0.16864302 | O6: Repeat rate | P6: =P5/P4 -> 0.58197747
A7: 4 | B7: Apr | C7: =SUMIFS(Clean_Data!$M$2:$M$2086,Clean_Data!$D$2:$D$2086,A7) -> 1742470 | D7: =SUMIFS(Clean_Data!$N$2:$N$2086,Clean_Data!$D$2:$D$2086,A7) -> 540320 | E7: =COUNTIFS(Clean_Data!$D$2:$D$2086,A7) -> 159 | F7: =IF(C6=0,0,C7/C6-1) -> 0.097905909 | G7: =C7/AVERAGE($C$4:$C$15) -> 1.0164241 | I7: 4-5 orders | J7: =COUNTIFS(Customers!$C$2:$C$800,">=4",Customers!$C$2:$C$800,"<=5") -> 114 | K7: =J7/$J$9 -> 0.14267835 | L7: =SUMIFS(Customers!$D$2:$D$800,Customers!$C$2:$C$800,">=4",Customers!$C$2:$C$800,"<=5") -> 5933232.5 | M7: =L7/$L$9 -> 0.28841627 | O7: Revenue from repeat customers | P7: =SUMIFS(Customers!$D$2:$D$800,Customers!$F$2:$F$800,"Repeat") -> 18157878
A8: 5 | B8: May | C8: =SUMIFS(Clean_Data!$M$2:$M$2086,Clean_Data!$D$2:$D$2086,A8) -> 2009810 | D8: =SUMIFS(Clean_Data!$N$2:$N$2086,Clean_Data!$D$2:$D$2086,A8) -> 629460 | E8: =COUNTIFS(Clean_Data!$D$2:$D$2086,A8) -> 177 | F8: =IF(C7=0,0,C8/C7-1) -> 0.15342588 | G8: =C8/AVERAGE($C$4:$C$15) -> 1.1723699 | I8: 6+ orders | J8: =COUNTIFS(Customers!$C$2:$C$800,">=6") -> 73 | K8: =J8/$J$9 -> 0.091364205 | L8: =SUMIFS(Customers!$D$2:$D$800,Customers!$C$2:$C$800,">=6") -> 5841982.5 | M8: =L8/$L$9 -> 0.28398058 | O8: Repeat revenue share | P8: =P7/Analysis!C16 -> 0.88266006
A9: 6 | B9: Jun | C9: =SUMIFS(Clean_Data!$M$2:$M$2086,Clean_Data!$D$2:$D$2086,A9) -> 1484227.5 | D9: =SUMIFS(Clean_Data!$N$2:$N$2086,Clean_Data!$D$2:$D$2086,A9) -> 439777.5 | E9: =COUNTIFS(Clean_Data!$D$2:$D$2086,A9) -> 154 | F9: =IF(C8=0,0,C9/C8-1) -> -0.26150855 | G9: =C9/AVERAGE($C$4:$C$15) -> 0.86578511 | I9: Total | J9: =SUM(J4:J8) -> 799 | K9: =SUM(K4:K8) -> 1 | L9: =SUM(L4:L8) -> 20571768 | M9: =SUM(M4:M8) -> 1 | O9: Top 10% customers revenue | P9: =SUM(Customers!$D$2:$D$81) -> 8729015
A10: 7 | B10: Jul | C10: =SUMIFS(Clean_Data!$M$2:$M$2086,Clean_Data!$D$2:$D$2086,A10) -> 1237125 | D10: =SUMIFS(Clean_Data!$N$2:$N$2086,Clean_Data!$D$2:$D$2086,A10) -> 389325 | E10: =COUNTIFS(Clean_Data!$D$2:$D$2086,A10) -> 128 | F10: =IF(C9=0,0,C10/C9-1) -> -0.1664856 | G10: =C10/AVERAGE($C$4:$C$15) -> 0.72164436 | O10: Top 10% share | P10: =P9/Analysis!C16 -> 0.42432013
A11: 8 | B11: Aug | C11: =SUMIFS(Clean_Data!$M$2:$M$2086,Clean_Data!$D$2:$D$2086,A11) -> 1856082.5 | D11: =SUMIFS(Clean_Data!$N$2:$N$2086,Clean_Data!$D$2:$D$2086,A11) -> 551032.5 | E11: =COUNTIFS(Clean_Data!$D$2:$D$2086,A11) -> 154 | F11: =IF(C10=0,0,C11/C10-1) -> 0.50031929 | G11: =C11/AVERAGE($C$4:$C$15) -> 1.082697 | O11: Top 20% customers revenue | P11: =SUM(Customers!$D$2:$D$161) -> 12806742
A12: 9 | B12: Sep | C12: =SUMIFS(Clean_Data!$M$2:$M$2086,Clean_Data!$D$2:$D$2086,A12) -> 1774650 | D12: =SUMIFS(Clean_Data!$N$2:$N$2086,Clean_Data!$D$2:$D$2086,A12) -> 562350 | E12: =COUNTIFS(Clean_Data!$D$2:$D$2086,A12) -> 182 | F12: =IF(C11=0,0,C12/C11-1) -> -0.043873319 | G12: =C12/AVERAGE($C$4:$C$15) -> 1.0351954 | I12: Customer Decile | J12: Customers | K12: Revenue | L12: Share of Revenue | O12: Top 20% share | P12: =P11/Analysis!C16 -> 0.62253973
A13: 10 | B13: Oct | C13: =SUMIFS(Clean_Data!$M$2:$M$2086,Clean_Data!$D$2:$D$2086,A13) -> 1724992.5 | D13: =SUMIFS(Clean_Data!$N$2:$N$2086,Clean_Data!$D$2:$D$2086,A13) -> 478242.5 | E13: =COUNTIFS(Clean_Data!$D$2:$D$2086,A13) -> 198 | F13: =IF(C12=0,0,C13/C12-1) -> -0.027981574 | G13: =C13/AVERAGE($C$4:$C$15) -> 1.006229 | I13: Decile 1 | J13: =ROWS(Customers!$D$2:$D$81) -> 80 | K13: =SUM(Customers!$D$2:$D$81) -> 8729015 | L13: =K13/$K$23 -> 0.42432013 | O13: Revenue per customer | P13: =Analysis!C16/P4 -> 25746.893
A14: 11 | B14: Nov | C14: =SUMIFS(Clean_Data!$M$2:$M$2086,Clean_Data!$D$2:$D$2086,A14) -> 2073995 | D14: =SUMIFS(Clean_Data!$N$2:$N$2086,Clean_Data!$D$2:$D$2086,A14) -> 618895 | E14: =COUNTIFS(Clean_Data!$D$2:$D$2086,A14) -> 262 | F14: =IF(C13=0,0,C14/C13-1) -> 0.20232117 | G14: =C14/AVERAGE($C$4:$C$15) -> 1.2098105 | I14: Decile 2 | J14: =ROWS(Customers!$D$82:$D$161) -> 80 | K14: =SUM(Customers!$D$82:$D$161) -> 4077727.5 | L14: =K14/$K$23 -> 0.1982196 | O14: Average order value | P14: =Analysis!C16/Analysis!E16 -> 9866.5552
A15: 12 | B15: Dec | C15: =SUMIFS(Clean_Data!$M$2:$M$2086,Clean_Data!$D$2:$D$2086,A15) -> 2096965 | D15: =SUMIFS(Clean_Data!$N$2:$N$2086,Clean_Data!$D$2:$D$2086,A15) -> 593715 | E15: =COUNTIFS(Clean_Data!$D$2:$D$2086,A15) -> 214 | F15: =IF(C14=0,0,C15/C14-1) -> 0.011075244 | G15: =C15/AVERAGE($C$4:$C$15) -> 1.2232094 | I15: Decile 3 | J15: =ROWS(Customers!$D$162:$D$241) -> 80 | K15: =SUM(Customers!$D$162:$D$241) -> 2618492.5 | L15: =K15/$K$23 -> 0.12728573
B16: Total | C16: =SUM(C4:C15) -> 20571768 | D16: =SUM(D4:D15) -> 6248167.5 | E16: =SUM(E4:E15) -> 2085 | I16: Decile 4 | J16: =ROWS(Customers!$D$242:$D$321) -> 80 | K16: =SUM(Customers!$D$242:$D$321) -> 1818160 | L16: =K16/$K$23 -> 0.088381322
I17: Decile 5 | J17: =ROWS(Customers!$D$322:$D$401) -> 80 | K17: =SUM(Customers!$D$322:$D$401) -> 1249615 | L17: =K17/$K$23 -> 0.060744173
I18: Decile 6 | J18: =ROWS(Customers!$D$402:$D$481) -> 80 | K18: =SUM(Customers!$D$402:$D$481) -> 808775 | L18: =K18/$K$23 -> 0.039314804
I19: Decile 7 | J19: =ROWS(Customers!$D$482:$D$561) -> 80 | K19: =SUM(Customers!$D$482:$D$561) -> 558697.5 | L19: =K19/$K$23 -> 0.027158459
I20: Decile 8 | J20: =ROWS(Customers!$D$562:$D$641) -> 80 | K20: =SUM(Customers!$D$562:$D$641) -> 359550 | L20: =K20/$K$23 -> 0.017477837
I21: Decile 9 | J21: =ROWS(Customers!$D$642:$D$721) -> 80 | K21: =SUM(Customers!$D$642:$D$721) -> 232615 | L21: =K21/$K$23 -> 0.011307487
I22: Decile 10 | J22: =ROWS(Customers!$D$722:$D$800) -> 79 | K22: =SUM(Customers!$D$722:$D$800) -> 119120 | L22: =K22/$K$23 -> 0.0057904602
I23: Total | J23: =SUM(J13:J22) -> 799 | K23: =SUM(K13:K22) -> 20571768 | L23: =SUM(L13:L22) -> 1
I24: Decile 1 = top 10% of customers by revenue
A27: Segment | B27: Customers | C27: Orders | D27: Revenue | E27: Profit | F27: Margin | G27: Revenue per Customer | H27: Avg Order Value
A28: Consumer | B28: =COUNTIFS(Customers!$B$2:$B$800,A28) -> 486 | C28: =COUNTIFS(Clean_Data!$F$2:$F$2086,A28) -> 1194 | D28: =SUMIFS(Clean_Data!$M$2:$M$2086,Clean_Data!$F$2:$F$2086,A28) -> 6629660 | E28: =SUMIFS(Clean_Data!$N$2:$N$2086,Clean_Data!$F$2:$F$2086,A28) -> 2136860 | F28: =E28/D28 -> 0.32231819 | G28: =D28/B28 -> 13641.276 | H28: =D28/C28 -> 5552.4791
A29: Small Business | B29: =COUNTIFS(Customers!$B$2:$B$800,A29) -> 214 | C29: =COUNTIFS(Clean_Data!$F$2:$F$2086,A29) -> 474 | D29: =SUMIFS(Clean_Data!$M$2:$M$2086,Clean_Data!$F$2:$F$2086,A29) -> 5374527.5 | E29: =SUMIFS(Clean_Data!$N$2:$N$2086,Clean_Data!$F$2:$F$2086,A29) -> 1732027.5 | F29: =E29/D29 -> 0.322266 | G29: =D29/B29 -> 25114.614 | H29: =D29/C29 -> 11338.666
A30: Corporate | B30: =COUNTIFS(Customers!$B$2:$B$800,A30) -> 99 | C30: =COUNTIFS(Clean_Data!$F$2:$F$2086,A30) -> 417 | D30: =SUMIFS(Clean_Data!$M$2:$M$2086,Clean_Data!$F$2:$F$2086,A30) -> 8567580 | E30: =SUMIFS(Clean_Data!$N$2:$N$2086,Clean_Data!$F$2:$F$2086,A30) -> 2379280 | F30: =E30/D30 -> 0.27770736 | G30: =D30/B30 -> 86541.212 | H30: =D30/C30 -> 20545.755
A31: Total | B31: =SUM(B28:B30) -> 799 | C31: =SUM(C28:C30) -> 2085 | D31: =SUM(D28:D30) -> 20571768 | E31: =SUM(E28:E30) -> 6248167.5 | F31: =E31/D31 -> 0.30372536 | G31: =D31/B31 -> 25746.893 | H31: =D31/C31 -> 9866.5552
A34: Category | B34: Revenue | C34: Profit | D34: Margin | E34: Share of Revenue
A35: Electronics | B35: =SUMIFS(Clean_Data!$M$2:$M$2086,Clean_Data!$G$2:$G$2086,A35) -> 5209825 | C35: =SUMIFS(Clean_Data!$N$2:$N$2086,Clean_Data!$G$2:$G$2086,A35) -> 1448125 | D35: =C35/B35 -> 0.27796039 | E35: =B35/$B$38 -> 0.25325121
A36: Furniture | B36: =SUMIFS(Clean_Data!$M$2:$M$2086,Clean_Data!$G$2:$G$2086,A36) -> 13243540 | C36: =SUMIFS(Clean_Data!$N$2:$N$2086,Clean_Data!$G$2:$G$2086,A36) -> 3768740 | D36: =C36/B36 -> 0.28457195 | E36: =B36/$B$38 -> 0.64377259
A37: Stationery | B37: =SUMIFS(Clean_Data!$M$2:$M$2086,Clean_Data!$G$2:$G$2086,A37) -> 2118402.5 | C37: =SUMIFS(Clean_Data!$N$2:$N$2086,Clean_Data!$G$2:$G$2086,A37) -> 1031302.5 | D37: =C37/B37 -> 0.48683029 | E37: =B37/$B$38 -> 0.1029762
A38: Total | B38: =SUM(B35:B37) -> 20571768 | C38: =SUM(C35:C37) -> 6248167.5 | D38: =C38/B38 -> 0.30372536 | E38: =SUM(E35:E37) -> 1
A41: Region | B41: Revenue | C41: Profit | D41: Orders | E41: Share of Revenue
A42: North | B42: =SUMIFS(Clean_Data!$M$2:$M$2086,Clean_Data!$E$2:$E$2086,A42) -> 5301452.5 | C42: =SUMIFS(Clean_Data!$N$2:$N$2086,Clean_Data!$E$2:$E$2086,A42) -> 1631502.5 | D42: =COUNTIFS(Clean_Data!$E$2:$E$2086,A42) -> 560 | E42: =B42/$B$47 -> 0.25770525
A43: South | B43: =SUMIFS(Clean_Data!$M$2:$M$2086,Clean_Data!$E$2:$E$2086,A43) -> 6853002.5 | C43: =SUMIFS(Clean_Data!$N$2:$N$2086,Clean_Data!$E$2:$E$2086,A43) -> 2095152.5 | D43: =COUNTIFS(Clean_Data!$E$2:$E$2086,A43) -> 719 | E43: =B43/$B$47 -> 0.33312658
A44: East | B44: =SUMIFS(Clean_Data!$M$2:$M$2086,Clean_Data!$E$2:$E$2086,A44) -> 4380590 | C44: =SUMIFS(Clean_Data!$N$2:$N$2086,Clean_Data!$E$2:$E$2086,A44) -> 1312040 | D44: =COUNTIFS(Clean_Data!$E$2:$E$2086,A44) -> 403 | E44: =B44/$B$47 -> 0.21294184
A45: West | B45: =SUMIFS(Clean_Data!$M$2:$M$2086,Clean_Data!$E$2:$E$2086,A45) -> 3901537.5 | C45: =SUMIFS(Clean_Data!$N$2:$N$2086,Clean_Data!$E$2:$E$2086,A45) -> 1169187.5 | D45: =COUNTIFS(Clean_Data!$E$2:$E$2086,A45) -> 393 | E45: =B45/$B$47 -> 0.18965495
A46: Unspecified | B46: =SUMIFS(Clean_Data!$M$2:$M$2086,Clean_Data!$E$2:$E$2086,A46) -> 135185 | C46: =SUMIFS(Clean_Data!$N$2:$N$2086,Clean_Data!$E$2:$E$2086,A46) -> 40285 | D46: =COUNTIFS(Clean_Data!$E$2:$E$2086,A46) -> 10 | E46: =B46/$B$47 -> 0.0065713848
A47: Total | B47: =SUM(B42:B46) -> 20571768 | C47: =SUM(C42:C46) -> 6248167.5 | D47: =SUM(D42:D46) -> 2085 | E47: =SUM(E42:E46) -> 1
